2023-04-04 03:40:11,753 INFO    StreamThr :42671 [internal.py:wandb_internal():87] W&B internal server running at pid: 42671, started at: 2023-04-04 03:40:11.752731
2023-04-04 03:40:11,758 DEBUG   HandlerThread:42671 [handler.py:handle_request():144] handle_request: status
2023-04-04 03:40:11,773 INFO    WriterThread:42671 [datastore.py:open_for_write():85] open: /home/shubham/Academics/Thesis/openfl/openfl-tutorials/interactive_api/PyTorch_MedMNIST_2D/wandb/run-20230404_034011-0dgxjycp/run-0dgxjycp.wandb
2023-04-04 03:40:11,774 DEBUG   SenderThread:42671 [sender.py:send():336] send: header
2023-04-04 03:40:11,804 DEBUG   SenderThread:42671 [sender.py:send():336] send: run
2023-04-04 03:40:12,676 ERROR   SenderThread:42671 [internal_api.py:execute():246] 403 response executing GraphQL.
2023-04-04 03:40:12,677 ERROR   SenderThread:42671 [internal_api.py:execute():247] {"errors":[{"message":"permission denied","path":["upsertBucket"],"extensions":{"code":"PERMISSION_ERROR"}}],"data":{"upsertBucket":null}}
2023-04-04 03:40:12,678 ERROR   SenderThread:42671 [sender.py:send_run():931] It appears that you do not have permission to access the requested resource. Please reach out to the project owner to grant you access. If you have the correct permissions, verify that there are no issues with your networking setup.(Error 403: Forbidden)
Traceback (most recent call last):
  File "/home/shubham/anaconda3/envs/openfl/lib/python3.8/site-packages/wandb/sdk/lib/retry.py", line 131, in __call__
    result = self._call_fn(*args, **kwargs)
  File "/home/shubham/anaconda3/envs/openfl/lib/python3.8/site-packages/wandb/sdk/internal/internal_api.py", line 243, in execute
    return self.client.execute(*args, **kwargs)  # type: ignore
  File "/home/shubham/anaconda3/envs/openfl/lib/python3.8/site-packages/wandb/vendor/gql-0.2.0/wandb_gql/client.py", line 52, in execute
    result = self._get_result(document, *args, **kwargs)
  File "/home/shubham/anaconda3/envs/openfl/lib/python3.8/site-packages/wandb/vendor/gql-0.2.0/wandb_gql/client.py", line 60, in _get_result
    return self.transport.execute(document, *args, **kwargs)
  File "/home/shubham/anaconda3/envs/openfl/lib/python3.8/site-packages/wandb/vendor/gql-0.2.0/wandb_gql/transport/requests.py", line 39, in execute
    request.raise_for_status()
  File "/home/shubham/anaconda3/envs/openfl/lib/python3.8/site-packages/requests/models.py", line 1021, in raise_for_status
    raise HTTPError(http_error_msg, response=self)
requests.exceptions.HTTPError: 403 Client Error: Forbidden for url: https://api.wandb.ai/graphql

During handling of the above exception, another exception occurred:

Traceback (most recent call last):
  File "/home/shubham/anaconda3/envs/openfl/lib/python3.8/site-packages/wandb/sdk/internal/sender.py", line 929, in send_run
    self._init_run(run, config_value_dict)
  File "/home/shubham/anaconda3/envs/openfl/lib/python3.8/site-packages/wandb/sdk/internal/sender.py", line 968, in _init_run
    server_run, inserted, server_messages = self._api.upsert_run(
  File "/home/shubham/anaconda3/envs/openfl/lib/python3.8/site-packages/wandb/apis/normalize.py", line 51, in wrapper
    raise err
  File "/home/shubham/anaconda3/envs/openfl/lib/python3.8/site-packages/wandb/apis/normalize.py", line 25, in wrapper
    return func(*args, **kwargs)
  File "/home/shubham/anaconda3/envs/openfl/lib/python3.8/site-packages/wandb/sdk/internal/internal_api.py", line 1664, in upsert_run
    response = self.gql(
  File "/home/shubham/anaconda3/envs/openfl/lib/python3.8/site-packages/wandb/sdk/internal/internal_api.py", line 215, in gql
    ret = self._retry_gql(
  File "/home/shubham/anaconda3/envs/openfl/lib/python3.8/site-packages/wandb/sdk/lib/retry.py", line 147, in __call__
    retry_timedelta_triggered = check_retry_fn(e)
  File "/home/shubham/anaconda3/envs/openfl/lib/python3.8/site-packages/wandb/util.py", line 1092, in check_retry_fn
    return fallback_retry_fn(e)
  File "/home/shubham/anaconda3/envs/openfl/lib/python3.8/site-packages/wandb/util.py", line 1034, in no_retry_auth
    raise CommError(
wandb.errors.CommError: It appears that you do not have permission to access the requested resource. Please reach out to the project owner to grant you access. If you have the correct permissions, verify that there are no issues with your networking setup.(Error 403: Forbidden)
2023-04-04 03:40:17,685 DEBUG   HandlerThread:42671 [handler.py:handle_request():144] handle_request: status_report
